Workbook
Name SegmentaciónDeDatos_DIA: #N/A

Sheet TD
D1: Juntas Distritales | N1: Dirección de Administración
N2: Subdirección de Recursos Materiales
N3: Departamento de Control Patrimonial
A7: DISTRITO | B7: H. EMBARQUE
A8: Amecameca de juarez | B8: 0.33333333
A9: CD. Nezahualcoyotl | B9: 0.52083333
A10: Chimaihuacan | B10: 0.4375
A11: Chimalhuacan | B11: 0.47916667
A12: Ixtapaluca | B12: 0.375
A13: Los Reyes Acaquilpan | B13: 0.47916667
A14: Naucalpan de Juarez | B14: 0.5625
B15: 0.60416667
A16: Total general
A19: DISTRITO | B19: Cuenta de ARTICULO
A20: Amecameca de juarez | B20: 12
A21: CD. Nezahualcoyotl | B21: 13
A22: Chimaihuacan | B22: 17
A23: Chimalhuacan | B23: 13
A24: Ixtapaluca | B24: 13
A25: Los Reyes Acaquilpan | B25: 17
A26: Naucalpan de Juarez | B26: 24
A27: Total general | B27: 109
A30: ARTICULOS | B30: Cuenta de ARTICULO
A31: BAFLE | B31: 8
A32: BOTIQUIN | B32: 8
A33: CAMARA DIGITAL | B33: 8
A34: ENGARGOLADORA | B34: 8
A35: EQUIPO DE PERIFONEO | B35: 8
A36: GRABADORA | B36: 8
A37: LAMPARA DE EMERGENCIA CHICA | B37: 29
A38: LAMPARA DE EMERGENCIA GRANDE | B38: 8
A39: RECEPTOR | B39: 8
A40: TAJALAPIZ | B40: 8
A41: TELEFONOS | B41: 8
A42: Total general | B42: 109

Sheet BD
L1: Dirección de Administración
L2: Subdirección de Recursos Materiales
L3: Departamento de Control Patrimonial
L4: ENVIO: FECHA
A5: CONCAT | B5: NP | C5: TOTAL | D5: CLAVE | E5: DISTRITO | F5: LOCALIDAD | G5: ARTICULO | H5: MARCA | I5: INVENTARIO 1 | J5: INVENTARIO M | K5: VALIDADOR | L5: OBSERVACIONES | M5: DIA | N5: RUTA | O5: H. EMBARQUE | P5: H. LLEGADA
A6: =D6&N6 -> 600125 | B6: 1 | C6: 13 | D6: 6001 | E6: Chalco de Diaz Covarrubias | F6: NA | G6: BAFLE | H6: STEREN | I6: IBAF00100183 | J6: IBAF00100183 | K6: 12 | L6: Incluye: Cable de Alimentación, | M6: =VLOOKUP(D6,HORARIOS!B:H,7,0) -> Dia 5 | N6: =VLOOKUP(D6,HORARIOS!B:I,8,0) -> 25 | O6: =VLOOKUP(D6,HORARIOS!B:D,3,0) -> 0.33333333 | P6: =VLOOKUP(A6,HORARIOS!A:E,5,0) -> 12:00 hrs
A7: =D7&N7 -> 600125 | B7: 2 | C7: 13 | D7: 6001 | E7: Chalco de Diaz Covarrubias | F7: NA | G7: BOTIQUIN | H7: SN | I7: ibot00100106 | J7: IBOT00100106 | K7: 12 | M7: =VLOOKUP(D7,HORARIOS!B:H,7,0) -> Dia 5 | N7: =VLOOKUP(D7,HORARIOS!B:I,8,0) -> 25 | O7: =VLOOKUP(D7,HORARIOS!B:D,3,0) -> 0.33333333 | P7: =VLOOKUP(A7,HORARIOS!A:E,5,0) -> 12:00 hrs
A8: =D8&N8 -> 600125 | B8: 3 | C8: 13 | D8: 6001 | E8: Chalco de Diaz Covarrubias | F8: NA | G8: CAMARA DIGITAL | H8: SONY | I8: ICAM00101794 | J8: ICAM00101794 | K8: 12 | L8: Incluye: Memoria de 4GB, Cargador y Pila. | M8: =VLOOKUP(D8,HORARIOS!B:H,7,0) -> Dia 5 | N8: =VLOOKUP(D8,HORARIOS!B:I,8,0) -> 25 | O8: =VLOOKUP(D8,HORARIOS!B:D,3,0) -> 0.33333333 | P8: =VLOOKUP(A8,HORARIOS!A:E,5,0) -> 12:00 hrs
A9: =D9&N9 -> 600125 | B9: 4 | C9: 13 | D9: 6001 | E9: Chalco de Diaz Covarrubias | F9: NA | G9: ENGARGOLADORA | H9: COMBO | I9: IENC00100144 | J9: IENC00100144 | K9: 12 | M9: =VLOOKUP(D9,HORARIOS!B:H,7,0) -> Dia 5 | N9: =VLOOKUP(D9,HORARIOS!B:I,8,0) -> 25 | O9: =VLOOKUP(D9,HORARIOS!B:D,3,0) -> 0.33333333 | P9: =VLOOKUP(A9,HORARIOS!A:E,5,0) -> 12:00 hrs
A10: =D10&N10 -> 600125 | B10: 5 | C10: 13 | D10: 6001 | E10: Chalco de Diaz Covarrubias | F10: NA | G10: EQUIPO DE PERIFONEO | H10: RADSON | I10: iamp00100132 | J10: IAMP00100132 | K10: 12 | M10: =VLOOKUP(D10,HORARIOS!B:H,7,0) -> Dia 5 | N10: =VLOOKUP(D10,HORARIOS!B:I,8,0) -> 25 | O10: =VLOOKUP(D10,HORARIOS!B:D,3,0) -> 0.33333333 | P10: =VLOOKUP(A10,HORARIOS!A:E,5,0) -> 12:00 hrs
A11: =D11&N11 -> 600125 | B11: 6 | C11: 13 | D11: 6001 | E11: Chalco de Diaz Covarrubias | F11: NA | G11: GRABADORA | H11: SONY | I11: IGRA00100332 | J11: IGRA00100332 | K11: 12 | M11: =VLOOKUP(D11,HORARIOS!B:H,7,0) -> Dia 5 | N11: =VLOOKUP(D11,HORARIOS!B:I,8,0) -> 25 | O11: =VLOOKUP(D11,HORARIOS!B:D,3,0) -> 0.33333333 | P11: =VLOOKUP(A11,HORARIOS!A:E,5,0) -> 12:00 hrs
A12: =D12&N12 -> 600125 | B12: 7 | C12: 13 | D12: 6001 | E12: Chalco de Diaz Covarrubias | F12: NA | G12: LAMPARA DE EMERGENCIA CHICA | H12: SURTEK | I12: ILAM00101145 | J12: ILAM00101145 | K12: 12 | L12: Incluye: Cable de Alimentacion (Lampara chica) | M12: =VLOOKUP(D12,HORARIOS!B:H,7,0) -> Dia 5 | N12: =VLOOKUP(D12,HORARIOS!B:I,8,0) -> 25 | O12: =VLOOKUP(D12,HORARIOS!B:D,3,0) -> 0.33333333 | P12: =VLOOKUP(A12,HORARIOS!A:E,5,0) -> 12:00 hrs
A13: =D13&N13 -> 600125 | B13: 8 | C13: 13 | D13: 6001 | E13: Chalco de Diaz Covarrubias | F13: NA | G13: LAMPARA DE EMERGENCIA CHICA | H13: SURTEK | I13: ILAM00101151 | J13: ILAM00101151 | K13: 12 | L13: Incluye: Cable de Alimentacion (Lampara chica) | M13: =VLOOKUP(D13,HORARIOS!B:H,7,0) -> Dia 5 | N13: =VLOOKUP(D13,HORARIOS!B:I,8,0) -> 25 | O13: =VLOOKUP(D13,HORARIOS!B:D,3,0) -> 0.33333333 | P13: =VLOOKUP(A13,HORARIOS!A:E,5,0) -> 12:00 hrs
A14: =D14&N14 -> 600125 | B14: 9 | C14: 13 | D14: 6001 | E14: Chalco de Diaz Covarrubias | F14: NA | G14: LAMPARA DE EMERGENCIA CHICA | H14: SURTEK | I14: ILAM00101157 | J14: ILAM00101157 | K14: 12 | L14: Incluye: Cable de Alimentacion (Lampara chica) | M14: =VLOOKUP(D14,HORARIOS!B:H,7,0) -> Dia 5 | N14: =VLOOKUP(D14,HORARIOS!B:I,8,0) -> 25 | O14: =VLOOKUP(D14,HORARIOS!B:D,3,0) -> 0.33333333 | P14: =VLOOKUP(A14,HORARIOS!A:E,5,0) -> 12:00 hrs
A15: =D15&N15 -> 600125 | B15: 10 | C15: 13 | D15: 6001 | E15: Chalco de Diaz Covarrubias | F15: NA | G15: LAMPARA DE EMERGENCIA GRANDE | H15: STEREN | I15: SN | J15: SN | K15: 2 | L15: Incluye: Cable de Alimentacion (Lampara grande) | M15: =VLOOKUP(D15,HORARIOS!B:H,7,0) -> Dia 5 | N15: =VLOOKUP(D15,HORARIOS!B:I,8,0) -> 25 | O15: =VLOOKUP(D15,HORARIOS!B:D,3,0) -> 0.33333333 | P15: =VLOOKUP(A15,HORARIOS!A:E,5,0) -> 12:00 hrs
A16: =D16&N16 -> 600125 | B16: 14 | C16: 13 | D16: 6001 | E16: Chalco de Diaz Covarrubias | F16: NA | G16: RECEPTOR | H16: SOUNDTRACK | I16: isis01200111 | J16: ISIS01200111 | K16: 12 | L16: Incluye: 2 Microfonos, Cable extencion Plug. Macho de 6.6mm, 2 Antenas y Eliminador y 2 soportes de microfonos | M16: =VLOOKUP(D16,HORARIOS!B:H,7,0) -> Dia 5 | N16: =VLOOKUP(D16,HORARIOS!B:I,8,0) -> 25 | O16: =VLOOKUP(D16,HORARIOS!B:D,3,0) -> 0.33333333 | P16: =VLOOKUP(A16,HORARIOS!A:E,5,0) -> 12:00 hrs
A17: =D17&N17 -> 600125 | B17: 15 | C17: 13 | D17: 6001 | E17: Chalco de Diaz Covarrubias | F17: NA | G17: TAJALAPIZ | H17: SN | I17: itaj00100201 | J17: ITAJ00100201 | K17: 12 | M17: =VLOOKUP(D17,HORARIOS!B:H,7,0) -> Dia 5 | N17: =VLOOKUP(D17,HORARIOS!B:I,8,0) -> 25 | O17: =VLOOKUP(D17,HORARIOS!B:D,3,0) -> 0.33333333 | P17: =VLOOKUP(A17,HORARIOS!A:E,5,0) -> 12:00 hrs
A18: =D18&N18 -> 600125 | B18: 16 | C18: 13 | D18: 6001 | E18: Chalco de Diaz Covarrubias | F18: NA | G18: TELEFONOS | H18: TELMEX | I18: itel00100425 | J18: ITEL00100425 | K18: 12 | M18: =VLOOKUP(D18,HORARIOS!B:H,7,0) -> Dia 5 | N18: =VLOOKUP(D18,HORARIOS!B:I,8,0) -> 25 | O18: =VLOOKUP(D18,HORARIOS!B:D,3,0) -> 0.33333333 | P18: =VLOOKUP(A18,HORARIOS!A:E,5,0) -> 12:00 hrs
A19: =D19&N19 -> 600212 | B19: 17 | C19: 12 | D19: 6002 | E19: Toluca de Lerdo | F19: NA | G19: BAFLE | H19: STEREN | I19: IBAF00100113 | J19: IBAF00100113 | K19: 12 | L19: Incluye: Cable de Alimentación, CON CABLE PLUS 3 VIAS | M19: =VLOOKUP(D19,HORARIOS!B:H,7,0) -> Día 2 | N19: =VLOOKUP(D19,HORARIOS!B:I,8,0) -> 12 | O19: =VLOOKUP(D19,HORARIOS!B:D,3,0) -> 0.60416667 | P19: =VLOOKUP(A19,HORARIOS!A:E,5,0) -> 16:30 hrs
A20: =D20&N20 -> 600212 | B20: 18 | C20: 12 | D20: 6002 | E20: Toluca de Lerdo | F20: NA | G20: BOTIQUIN | H20: SN | I20: IBOT00100182 | J20: IBOT00100182 | K20: 12 | M20: =VLOOKUP(D20,HORARIOS!B:H,7,0) -> Día 2 | N20: =VLOOKUP(D20,HORARIOS!B:I,8,0) -> 12 | O20: =VLOOKUP(D20,HORARIOS!B:D,3,0) -> 0.60416667 | P20: =VLOOKUP(A20,HORARIOS!A:E,5,0) -> 16:30 hrs
A21: =D21&N21 -> 600212 | B21: 19 | C21: 12 | D21: 6002 | E21: Toluca de Lerdo | F21: NA | G21: CAMARA DIGITAL | H21: SONY | I21: icam00101757 | J21: ICAM00101757 | K21: 12 | M21: =VLOOKUP(D21,HORARIOS!B:H,7,0) -> Día 2 | N21: =VLOOKUP(D21,HORARIOS!B:I,8,0) -> 12 | O21: =VLOOKUP(D21,HORARIOS!B:D,3,0) -> 0.60416667 | P21: =VLOOKUP(A21,HORARIOS!A:E,5,0) -> 16:30 hrs
A22: =D22&N22 -> 600212 | B22: 20 | C22: 12 | D22: 6002 | E22: Toluca de Lerdo | F22: NA | G22: ENGARGOLADORA | H22: COMBO | I22: ieng00100126 | J22: IENG00100126 | K22: 12 | M22: =VLOOKUP(D22,HORARIOS!B:H,7,0) -> Día 2 | N22: =VLOOKUP(D22,HORARIOS!B:I,8,0) -> 12 | O22: =VLOOKUP(D22,HORARIOS!B:D,3,0) -> 0.60416667 | P22: =VLOOKUP(A22,HORARIOS!A:E,5,0) -> 16:30 hrs
A23: =D23&N23 -> 600212 | B23: 21 | C23: 12 | D23: 6002 | E23: Toluca de Lerdo | F23: NA | G23: EQUIPO DE PERIFONEO | H23: RADSON | I23: IAMP00100061 | J23: IAMP00100061 | K23: 12 | M23: =VLOOKUP(D23,HORARIOS!B:H,7,0) -> Día 2 | N23: =VLOOKUP(D23,HORARIOS!B:I,8,0) -> 12 | O23: =VLOOKUP(D23,HORARIOS!B:D,3,0) -> 0.60416667 | P23: =VLOOKUP(A23,HORARIOS!A:E,5,0) -> 16:30 hrs
A24: =D24&N24 -> 600212 | B24: 22 | C24: 12 | D24: 6002 | E24: Toluca de Lerdo | F24: NA | G24: GRABADORA | H24: SONY | I24: igra00100377 | J24: IGRA00100377 | K24: 12 | M24: =VLOOKUP(D24,HORARIOS!B:H,7,0) -> Día 2 | N24: =VLOOKUP(D24,HORARIOS!B:I,8,0) -> 12 | O24: =VLOOKUP(D24,HORARIOS!B:D,3,0) -> 0.60416667 | P24: =VLOOKUP(A24,HORARIOS!A:E,5,0) -> 16:30 hrs
A25: =D25&N25 -> 600212 | B25: 23 | C25: 12 | D25: 6002 | E25: Toluca de Lerdo | F25: NA | G25: LAMPARA DE EMERGENCIA CHICA | H25: SURTEK | I25: ILAM00101251 | J25: ILAM00101251 | K25: 12 | L25: Incluye: Cable de Alimentacion (Lampara chica) | M25: =VLOOKUP(D25,HORARIOS!B:H,7,0) -> Día 2 | N25: =VLOOKUP(D25,HORARIOS!B:I,8,0) -> 12 | O25: =VLOOKUP(D25,HORARIOS!B:D,3,0) -> 0.60416667 | P25: =VLOOKUP(A25,HORARIOS!A:E,5,0) -> 16:30 hrs
A26: =D26&N26 -> 600212 | B26: 24 | C26: 12 | D26: 6002 | E26: Toluca de Lerdo | F26: NA | G26: LAMPARA DE EMERGENCIA CHICA | H26: SURTEK | I26: ILAM00101321 | J26: ILAM00101321 | K26: 12 | L26: Incluye: Cable de Alimentacion (Lampara chica) | M26: =VLOOKUP(D26,HORARIOS!B:H,7,0) -> Día 2 | N26: =VLOOKUP(D26,HORARIOS!B:I,8,0) -> 12 | O26: =VLOOKUP(D26,HORARIOS!B:D,3,0) -> 0.60416667 | P26: =VLOOKUP(A26,HORARIOS!A:E,5,0) -> 16:30 hrs
A27: =D27&N27 -> 600212 | B27: 25 | C27: 12 | D27: 6002 | E27: Toluca de Lerdo | F27: NA | G27: LAMPARA DE EMERGENCIA GRANDE | H27: STEREN | I27: SN | J27: SN | K27: 2 | L27: Incluye: Cable de Alimentacion (Lampara grande) | M27: =VLOOKUP(D27,HORARIOS!B:H,7,0) -> Día 2 | N27: =VLOOKUP(D27,HORARIOS!B:I,8,0) -> 12 | O27: =VLOOKUP(D27,HORARIOS!B:D,3,0) -> 0.60416667 | P27: =VLOOKUP(A27,HORARIOS!A:E,5,0) -> 16:30 hrs
A28: =D28&N28 -> 600212 | B28: 26 | C28: 12 | D28: 6002 | E28: Toluca de Lerdo | F28: NA | G28: RECEPTOR | H28: SOUNDTRACK | I28: isis01200114 | J28: ISIS01200114 | K28: 12 | L28: Incluye: 2 Microfonos, Cable extencion Plug. Macho de 6.6mm, 2 Antenas y Eliminador y 2 soportes de microfonos | M28: =VLOOKUP(D28,HORARIOS!B:H,7,0) -> Día 2 | N28: =VLOOKUP(D28,HORARIOS!B:I,8,0) -> 12 | O28: =VLOOKUP(D28,HORARIOS!B:D,3,0) -> 0.60416667 | P28: =VLOOKUP(A28,HORARIOS!A:E,5,0) -> 16:30 hrs
A29: =D29&N29 -> 600212 | B29: 27 | C29: 12 | D29: 6002 | E29: Toluca de Lerdo | F29: NA | G29: TAJALAPIZ | H29: SN | I29: ITAJ00100169 | J29: ITAJ00100169 | K29: 12 | M29: =VLOOKUP(D29,HORARIOS!B:H,7,0) -> Día 2 | N29: =VLOOKUP(D29,HORARIOS!B:I,8,0) -> 12 | O29: =VLOOKUP(D29,HORARIOS!B:D,3,0) -> 0.60416667 | P29: =VLOOKUP(A29,HORARIOS!A:E,5,0) -> 16:30 hrs
A30: =D30&N30 -> 600212 | B30: 28 | C30: 12 | D30: 6002 | E30: Toluca de Lerdo | F30: NA | G30: TELEFONOS | H30: TELMEX | I30: ITEL00101131 | J30: ITEL00101131 | K30: 12 | M30: =VLOOKUP(D30,HORARIOS!B:H,7,0) -> Día 2 | N30: =VLOOKUP(D30,HORARIOS!B:I,8,0) -> 12 | O30: =VLOOKUP(D30,HORARIOS!B:D,3,0) -> 0.60416667 | P30: =VLOOKUP(A30,HORARIOS!A:E,5,0) -> 16:30 hrs
A31: =D31&N31 -> 60032 | B31: 29 | C31: 17 | D31: 6003 | E31: Chimaihuacan | F31: NA | G31: BAFLE | H31: STEREN | I31: IBAF00100196 | J31: IBAF00100196 | K31: 12 | L31: Incluye: Cable de Alimentación, | M31: =VLOOKUP(D31,HORARIOS!B:H,7,0) -> Día 1 | N31: =VLOOKUP(D31,HORARIOS!B:I,8,0) -> 2 | O31: =VLOOKUP(D31,HORARIOS!B:D,3,0) -> 0.4375 | P31: =VLOOKUP(A31,HORARIOS!A:E,5,0) -> 14:00 hrs
A32: =D32&N32 -> 60032 | B32: 30 | C32: 17 | D32: 6003 | E32: Chimaihuacan | F32: NA | G32: BOTIQUIN | H32: SN | I32: IBOT00100067 | J32: IBOT00100067 | K32: 12 | M32: =VLOOKUP(D32,HORARIOS!B:H,7,0) -> Día 1 | N32: =VLOOKUP(D32,HORARIOS!B:I,8,0) -> 2 | O32: =VLOOKUP(D32,HORARIOS!B:D,3,0) -> 0.4375 | P32: =VLOOKUP(A32,HORARIOS!A:E,5,0) -> 14:00 hrs
A33: =D33&N33 -> 60032 | B33: 31 | C33: 17 | D33: 6003 | E33: Chimaihuacan | F33: NA | G33: CAMARA DIGITAL | H33: SONY | I33: ICAM00101745 | J33: ICAM00101745 | K33: 12 | L33: Incluye: Memoria de 4GB, Cargador y Pila. | M33: =VLOOKUP(D33,HORARIOS!B:H,7,0) -> Día 1 | N33: =VLOOKUP(D33,HORARIOS!B:I,8,0) -> 2 | O33: =VLOOKUP(D33,HORARIOS!B:D,3,0) -> 0.4375 | P33: =VLOOKUP(A33,HORARIOS!A:E,5,0) -> 14:00 hrs
A34: =D34&N34 -> 60032 | B34: 32 | C34: 17 | D34: 6003 | E34: Chimaihuacan | F34: NA | G34: ENGARGOLADORA | H34: COMBO | I34: IENG00100216 | J34: IENG00100216 | K34: 12 | M34: =VLOOKUP(D34,HORARIOS!B:H,7,0) -> Día 1 | N34: =VLOOKUP(D34,HORARIOS!B:I,8,0) -> 2 | O34: =VLOOKUP(D34,HORARIOS!B:D,3,0) -> 0.4375 | P34: =VLOOKUP(A34,HORARIOS!A:E,5,0) -> 14:00 hrs
A35: =D35&N35 -> 60032 | B35: 33 | C35: 17 | D35: 6003 | E35: Chimaihuacan | F35: NA | G35: EQUIPO DE PERIFONEO | H35: RADSON | I35: IAMP00100045 | J35: IAMP00100045 | K35: 12 | M35: =VLOOKUP(D35,HORARIOS!B:H,7,0) -> Día 1 | N35: =VLOOKUP(D35,HORARIOS!B:I,8,0) -> 2 | O35: =VLOOKUP(D35,HORARIOS!B:D,3,0) -> 0.4375 | P35: =VLOOKUP(A35,HORARIOS!A:E,5,0) -> 14:00 hrs
A36: =D36&N36 -> 60032 | B36: 35 | C36: 17 | D36: 6003 | E36: Chimaihuacan | F36: NA | G36: GRABADORA | H36: SONY | I36: IGRA00100313 | J36: IGRA00100313 | K36: 12 | M36: =VLOOKUP(D36,HORARIOS!B:H,7,0) -> Día 1 | N36: =VLOOKUP(D36,HORARIOS!B:I,8,0) -> 2 | O36: =VLOOKUP(D36,HORARIOS!B:D,3,0) -> 0.4375 | P36: =VLOOKUP(A36,HORARIOS!A:E,5,0) -> 14:00 hrs
A37: =D37&N37 -> 60032 | B37: 36 | C37: 17 | D37: 6003 | E37: Chimaihuacan | F37: NA | G37: LAMPARA DE EMERGENCIA CHICA | H37: SURTEK | I37: ILAM00101323 | J37: ILAM00101323 | K37: 12 | L37: Incluye: Cable de Alimentacion (Lampara chica) | M37: =VLOOKUP(D37,HORARIOS!B:H,7,0) -> Día 1 | N37: =VLOOKUP(D37,HORARIOS!B:I,8,0) -> 2 | O37: =VLOOKUP(D37,HORARIOS!B:D,3,0) -> 0.4375 | P37: =VLOOKUP(A37,HORARIOS!A:E,5,0) -> 14:00 hrs
A38: =D38&N38 -> 60032 | B38: 37 | C38: 17 | D38: 6003 | E38: Chimaihuacan | F38: NA | G38: LAMPARA DE EMERGENCIA CHICA | H38: SURTEK | I38: ILAM00101167 | J38: ILAM00101167 | K38: 12 | L38: Incluye: Cable de Alimentacion (Lampara chica) | M38: =VLOOKUP(D38,HORARIOS!B:H,7,0) -> Día 1 | N38: =VLOOKUP(D38,HORARIOS!B:I,8,0) -> 2 | O38: =VLOOKUP(D38,HORARIOS!B:D,3,0) -> 0.4375 | P38: =VLOOKUP(A38,HORARIOS!A:E,5,0) -> 14:00 hrs
A39: =D39&N39 -> 60032 | B39: 38 | C39: 17 | D39: 6003 | E39: Chimaihuacan | F39: NA | G39: LAMPARA DE EMERGENCIA CHICA | H39: SURTEK | I39: ILAM00100811 | J39: ILAM00100811 | K39: 12 | L39: Incluye: Cable de Alimentacion (Lampara chica) | M39: =VLOOKUP(D39,HORARIOS!B:H,7,0) -> Día 1 | N39: =VLOOKUP(D39,HORARIOS!B:I,8,0) -> 2 | O39: =VLOOKUP(D39,HORARIOS!B:D,3,0) -> 0.4375 | P39: =VLOOKUP(A39,HORARIOS!A:E,5,0) -> 14:00 hrs
A40: =D40&N40 -> 60032 | B40: 40 | C40: 17 | D40: 6003 | E40: Chimaihuacan | F40: NA | G40: LAMPARA DE EMERGENCIA CHICA | H40: SURTEK | I40: ILAM00101224 | J40: ILAM00101224 | K40: 12 | L40: Incluye: Cable de Alimentacion (Lampara chica) | M40: =VLOOKUP(D40,HORARIOS!B:H,7,0) -> Día 1 | N40: =VLOOKUP(D40,HORARIOS!B:I,8,0) -> 2 | O40: =VLOOKUP(D40,HORARIOS!B:D,3,0) -> 0.4375 | P40: =VLOOKUP(A40,HORARIOS!A:E,5,0) -> 14:00 hrs
...

Sheet CAJAS
E2: Dirección de Administración
E3: Subdirección de Recursos Materiales
E4: Departamento de Control Patrimonial
E5: ENVIO: FECHA
A6: =VLOOKUP(A9,[1]BD!C:D,2,0) -> Chalco de Diaz Covarrubias
A8: CLAVE | E8: LOCALIDAD
A9: 6001
A10: N.P | B10: ARTICULO | C10: MARCA | D10: INVENTARIO | E10: OBSERVACIONES
A11: 1 | B11: BAFLE | C11: STEREN | D11: IBAF00100183 | E11: Incluye: Cable de Alimentación, | F11: Cargado | H11: Eliminador | J11: (Plug 6.6mm a Cannon Macho)
A12: 2 | B12: BOTIQUIN | C12: SN | D12: IBOT00100106
A13: 3 | B13: CAMARA DIGITAL | C13: SONY | D13: ICAM00101794 | E13: Incluye: Memoria de 4GB, Cargador y Pila.
A14: 4 | B14: ENGARGOLADORA | C14: COMBO | D14: IENC00100144
A15: 5 | B15: EQUIPO DE PERIFONEO | C15: RADSON | D15: IAMP00100132
A16: 6 | B16: GRABADORA | C16: SONY | D16: IGRA00100332
A17: 7 | B17: LAMPARA DE EMERGENCIA CHICA | C17: SURTEK | D17: ILAM00101145 | E17: Incluye: Cable de Alimentacion (Lampara chica)
A18: 8 | B18: LAMPARA DE EMERGENCIA CHICA | C18: SURTEK | D18: ILAM00101151 | E18: Incluye: Cable de Alimentacion (Lampara chica)
A19: 9 | B19: LAMPARA DE EMERGENCIA CHICA | C19: SURTEK | D19: ILAM00101157 | E19: Incluye: Cable de Alimentacion (Lampara chica)
A20: 10 | B20: LAMPARA DE EMERGENCIA GRANDE | C20: STEREN | D20: SN | E20: Incluye: Cable de Alimentacion (Lampara grande)
A21: 11 | B21: RECEPTOR | C21: SOUNDTRACK | D21: ISIS01200111 | E21: Incluye: 2 Microfonos, Cable extencion Plug. Macho de 6.6mm, 2 Antenas y Eliminador y 2 soportes de microfonos
A22: 12 | B22: TAJALAPIZ | C22: SN | D22: ITAJ00100201
A23: 13 | B23: TELEFONOS | C23: TELMEX | D23: ITEL00100425
E31: Dirección de Administración
E32: Subdirección de Recursos Materiales
E33: Departamento de Control Patrimonial
E34: ENVIO: FECHA
A35: =VLOOKUP(A38,[1]BD!C:D,2,0) -> Toluca de Lerdo
A37: CLAVE | E37: LOCALIDAD
A38: 6002
A39: N.P | B39: ARTICULO | C39: MARCA | D39: INVENTARIO | E39: OBSERVACIONES
A40: 1 | B40: BAFLE | C40: STEREN | D40: IBAF00100113 | E40: Incluye: Cable de Alimentación, CON CABLE PLUS 3 VIAS
A41: 2 | B41: BOTIQUIN | C41: SN | D41: IBOT00100182
A42: 3 | B42: CAMARA DIGITAL | C42: SONY | D42: ICAM00101757
A43: 4 | B43: ENGARGOLADORA | C43: COMBO | D43: IENG00100126
A44: 5 | B44: EQUIPO DE PERIFONEO | C44: RADSON | D44: IAMP00100061
A45: 6 | B45: GRABADORA | C45: SONY | D45: IGRA00100377
A46: 7 | B46: LAMPARA DE EMERGENCIA CHICA | C46: SURTEK | D46: ILAM00101251 | E46: Incluye: Cable de Alimentacion (Lampara chica)
A47: 8 | B47: LAMPARA DE EMERGENCIA CHICA | C47: SURTEK | D47: ILAM00101321 | E47: Incluye: Cable de Alimentacion (Lampara chica)
A48: 9 | B48: LAMPARA DE EMERGENCIA GRANDE | C48: STEREN | D48: SN | E48: Incluye: Cable de Alimentacion (Lampara grande)
A49: 10 | B49: RECEPTOR | C49: SOUNDTRACK | D49: ISIS01200114 | E49: Incluye: 2 Microfonos, Cable extencion Plug. Macho de 6.6mm, 2 Antenas y Eliminador y 2 soportes de microfonos
A50: 11 | B50: TAJALAPIZ | C50: SN | D50: ITAJ00100169
...

Sheet RUTAS
A3: Programa de equipamiento de los Órganos Desconcentrados Distritales
A4: Proceso Electoral 2026 - 2027
A6: Día | B6: Ruta | C6: Centro de Costo | D6: Distrito Electoral | E6: Tiempos y distancias aproximadas | G6: Volumen
E7: Hora de embarque | F7: Hora de llegada | G7: m3
A9: Día 1 | B9: 1 | C9: 6028 | D9: Amecameca de Juárez | E9: 08:00 hrs | F9: 13:00 hrs | G9: 70
C10: 6040 | D10: Ixtapaluca | E10: 09.00 hrs | F10: 16:30 hrs
B11: 2 | C11: 6003 | D11: Chimalhuacán | E11: 10:30 hrs | F11: 14:00 hrs | G11: 50
B12: 3 | C12: 6005 | D12: Chimalhuacán | E12: 11:30 hrs | F12: 15:00 hrs | G12: 70
B13: 4 | C13: 6031 | D13: Los Reyes Acaquilpan | E13: 11:30 hrs | F13: 16:00 hrs | G13: 70
C14: 6041 | D14: Cd. Nezahualcóyotl | E14: 12:30 hrs | F14: 18:00 hrs
B15: 5 | C15: 6032 | D15: Naucalpan de Juárez | E15: 13.30 hrs | F15: 17:00 hrs | G15: 50
B16: 6 | C16: 6030 | D16: Naucalpan de Juárez | E16: 14:30 hrs | F16: 18:0 hrs | G16: 50
A17: Día 2 | B17: 7 | C17: 6006 | D17: Ecatepec de Morelos | E17: 08:00 hrs | F17: 12:00 hrs | G17: 70
B18: 8 | C18: 6021 | D18: Ecatepec de Morelos | E18: 09:30 hrs | F18: 13:30 hrs | G18: 70
B19: 9 | C19: 6020 | D19: Zumpango de Ocampo | E19: 10:30 hrs | F19: 14:30 hrs | G19: 50
B20: 10 | C20: 6026 | D20: Cuautitlán Izcalli | E20: 11:30 hrs | F20: 15:00 hrs | G20: 70
B21: 11 | C21: 6012 | D21: Teoloyucan | E21: 12:30 hrs | F21: 17:00 hrs | G21: 70
C22: 6043 | D22: Cuautitlán Izcalli | E22: 13:30 hrs | F22: 19:00 hrs
B23: 12 | C23: 6002 | D23: Toluca de Lerdo | E23: 14:30 hrs | F23: 16:30 hrs | G23: 70
B24: 13 | C24: 6034 | D24: Toluca de Lerdo | E24: 15:30 hrs | F24: 18:30 hrs | G24: 70
A25: Día 3 | B25: 14 | C25: 6022 | D25: Ojo de Agua (Tecámac) | E25: 08:00 hrs | F25: 12:00 hrs | G25: 70
B26: 15 | C26: 6033 | D26: Ojo de agua (Tecámac) | E26: 09:00 hrs | F26: 13:00 hrs | G26: 70
B27: 16 | C27: 6042 | D27: Ecatepec de Morelos | E27: 10:00 hrs | F27: 13:30 hrs | G27: 50
B28: 17 | C28: 6008 | D28: Ecatepec de Morelos | E28: 11:00 hrs | F28: 15:00 hrs | G28: 50
B29: 18 | C29: 6015 | D29: Ixtlahuaca de Rayón | E29: 12:00 hrs | F29: 14:30 hrs | G29: 70
C30: 6045 | D30: Barrio la Cabecera 3a Sección (Almoloya de Juárez) | E30: 13:00 hrs | F30: 16:00 hrs
B31: 19 | C31: 6036 | D31: San Miguel Zinacantepec | E31: 14:00 hrs | F31: 17:30 hrs | G31: 70
C32: 6035 | D32: Metepec | E32: 15:00 hrs | F32: 19:00 hrs
A33: Día 4 | B33: 22 | C33: 6023 | D33: Texcoco de Mora | E33: 08:00 hrs | F33: 12:30 hrs | G33: 70
C34: 6039 | D34: Tepexpan (Acolman) | E34: 09:00 hrs | F34: 13:00 hrs
B35: 20 | C35: 6037 | D35: Tlalnepantla de Baz | E35: 10:00 hrs | F35: 13:30 hrs | G35: 70
B36: 21 | C36: 6018 | D36: Tlalnepantla de Baz | E36: 11:00 hrs | F36: 14:30 hrs | G36: 70
B37: 23 | C37: 6014 | D37: Jilotepec de Andrés Molina Enríquez | E37: 12:00 hrs | F37: 16:00 hrs | G37: 70
C38: 6013 | D38: Atlacomulco de Fabela | E38: 13:00 hrs | F38: 18:30 hrs
B39: 24 | C39: 6004 | D39: Lerma de Villada | E39: 14:00 hrs | F39: 17:00 hrs | G39: 70
C40: 6017 | D40: Huixquilucan de Degollado | E40: 15:00 hrs | F40: 19:30 hrs
A41: Dia 5 | B41: 25 | C41: 6001 | D41: Chalco de Díaz Covarrubias | E41: 08:00 hrs | F41: 12:00 hrs | G41: 70
B42: 26 | C42: 6027 | D42: Valle de Chalco Solidaridad | E42: 09:00 hrs | F42: 13:00 hrs | G42: 50
B43: 27 | C43: 6044 | D43: Nicolás Romero | E43: 10:00 hrs | F43: 13:30 hrs | G43: 50
B44: 28 | C44: 6016 | D44: Ciudad Adolfo López Mateos | E44: 11:00 hrs | F44: 15:30 hrs | G44: 70
...

Sheet DIAS
F2: Dirección de Administración
F3: Subdirección de Recursos Materiales
F4: Departamento de Control Patrimonial
F5: ENVIO: FECHA
A6: DÍA 1
D20: Tiempos y distancias aproximadas
A21: Ruta | B21: Centro de Costo | C21: Distrito Electoral | D21: Hora de embarque | E21: Hora de llegada | F21: Volumen m3
A22: 1 | B22: 6028 | C22: Amecameca de Juárez | D22: 08:00 hrs | E22: 13:00 hrs | F22: 70
B23: 6040 | C23: Ixtapaluca | D23: 09.00 hrs | E23: 16:30 hrs
A24: 2 | B24: 6003 | C24: Chimalhuacán | D24: 10:30 hrs | E24: 14:00 hrs | F24: 50
A25: 3 | B25: 6005 | C25: Chimalhuacán | D25: 11:30 hrs | E25: 15:00 hrs | F25: 70
A26: 4 | B26: 6031 | C26: Los Reyes Acaquilpan | D26: 11:30 hrs | E26: 16:00 hrs | F26: 70
B27: 6041 | C27: Cd. Nezahualcóyotl | D27: 12:30 hrs | E27: 18:00 hrs
A28: 5 | B28: 6032 | C28: Naucalpan de Juárez | D28: 13.30 hrs | E28: 17:00 hrs | F28: 50
A29: 6 | B29: 6030 | C29: Naucalpan de Juárez | D29: 14:30 hrs | E29: 18:0 hrs | F29: 50
F33: Dirección de Administración
F34: Subdirección de Recursos Materiales
F35: Departamento de Control Patrimonial
F36: ENVIO: FECHA
A37: DÍA 2
D51: Tiempos y distancias aproximadas
A52: Ruta | B52: Centro de Costo | C52: Distrito Electoral | D52: Hora de embarque | E52: Hora de llegada | F52: Volumen m3
A53: 7 | B53: 6006 | C53: Ecatepec de Morelos | D53: 08:00 hrs | E53: 12:00 hrs | F53: 70
A54: 8 | B54: 6021 | C54: Ecatepec de Morelos | D54: 09:30 hrs | E54: 13:30 hrs | F54: 70
A55: 9 | B55: 6020 | C55: Zumpango de Ocampo | D55: 10:30 hrs | E55: 14:30 hrs | F55: 50
A56: 10 | B56: 6026 | C56: Cuautitlán Izcalli | D56: 11:30 hrs | E56: 15:00 hrs | F56: 70
A57: 11 | B57: 6012 | C57: Teoloyucan | D57: 12:30 hrs | E57: 17:00 hrs | F57: 70
B58: 6043 | C58: Cuautitlán Izcalli | D58: 13:30 hrs | E58: 19:00 hrs
A59: 12 | B59: 6002 | C59: Toluca de Lerdo | D59: 14:30 hrs | E59: 16:30 hrs | F59: 70
A60: 13 | B60: 6034 | C60: Toluca de Lerdo | D60: 15:30 hrs | E60: 18:30 hrs | F60: 70
F65: Dirección de Administración
F66: Subdirección de Recursos Materiales
F67: Departamento de Control Patrimonial
F68: ENVIO: FECHA
A69: DÍA 3
D83: Tiempos y distancias aproximadas
A84: Ruta | B84: Centro de Costo | C84: Distrito Electoral | D84: Hora de embarque | E84: Hora de llegada | F84: Volumen m3
A85: 14 | B85: 6022 | C85: Ojo de Agua (Tecámac) | D85: 08:00 hrs | E85: 12:00 hrs | F85: 70
A86: 15 | B86: 6033 | C86: Ojo de agua (Tecámac) | D86: 09:00 hrs | E86: 13:00 hrs | F86: 70
A87: 16 | B87: 6042 | C87: Ecatepec de Morelos | D87: 10:00 hrs | E87: 13:30 hrs | F87: 50
...

Sheet ST
E3: VALIDACION
A4: CLAVE | B4: DISTRITO | C4: Cuenta de ARTICULO | D4: Cuenta de TOTAL | E4: =D4-C4 -> #VALUE!
A5: 6001 | B5: Chalco de Diaz Covarrubias | C5: 13 | D5: 13 | E5: =GETPIVOTDATA("Cuenta de TOTAL",$A$3,"CLAVE",6002,"DISTRITO","Toluca de Lerdo")-GETPIVOTDATA("Cuenta de ARTICULO",$A$3,"CLAVE",6002,"DISTRITO","Toluca de Lerdo") -> 0
A6: 6002 | B6: Toluca de Lerdo | C6: 12 | D6: 12 | E6: =GETPIVOTDATA("Cuenta de TOTAL",$A$3,"CLAVE",6003,"DISTRITO","Chimaihuacan")-GETPIVOTDATA("Cuenta de ARTICULO",$A$3,"CLAVE",6003,"DISTRITO","Chimaihuacan") -> 0
A7: 6003 | B7: Chimaihuacan | C7: 17 | D7: 17
A8: 6004 | B8: Lerma de Villada | C8: 12 | D8: 12
A9: 6005 | B9: Chimalhuacan | C9: 13 | D9: 13
A10: 6006 | B10: Ecatepec de Morelos | C10: 13 | D10: 13
A11: 6007 | B11: Tenancingo de Degollado | C11: 15 | D11: 15
A12: 6008 | B12: Ecatepec de Morelos | C12: 16 | D12: 16
A13: 6009 | B13: Tejupilco de Hidalgo | C13: 14 | D13: 14
A14: 6010 | B14: Valle de Bravo | C14: 13 | D14: 13
A15: 6011 | B15: Tultitlan de Mariano Escobedo | C15: 13 | D15: 13
A16: 6012 | B16: Teoloyucan | C16: 13 | D16: 13
A17: 6013 | B17: Atlacomulco de Fabela | C17: 13 | D17: 13
A18: 6014 | B18: Jilotepec de Andres Molina Enriquez | C18: 11 | D18: 11
... A29: 6025 | B29: CD Nezahualcoyotl | C29: 13 | D29: 13
A30: Total general | C30: 334 | D30: 334

Sheet CONCAT
A1: ILAM00 | B1: 1011 | C1: 45 | D1: =CONCATENATE(A1,"",B1,"",C1) -> ILAM00101145 | E1: =D1 -> ILAM00101145
A2: ILAM00 | B2: 1011 | C2: 51 | D2: =CONCATENATE(A2,"",B2,"",C2) -> ILAM00101151 | E2: =D2 -> ILAM00101151
A3: ILAM00 | B3: 1011 | C3: 57 | D3: =CONCATENATE(A3,"",B3,"",C3) -> ILAM00101157 | E3: =D3 -> ILAM00101157

Sheet BESE TOTAL CAJA
A1: Clave | B1: Localidad | C1: Bafle | D1: Botiquín | E1: Cámara Fotográfica | F1: Engargoladora | G1: Equipo de Perifoneo | H1: Grabadora digital | I1: Lámpara de emergencia CHICA | J1: Lámpara de emergencia GRANDE | K1: Receptor | L1: Tajalápiz | M1: Teléfono | N1: TOTAL
A2: 6001 | B2: Chalco de Diaz Covarrubias | C2: 1 | D2: 1 | E2: 1 | F2: 1 | G2: 1 | H2: 1 | I2: 3 | J2: 1 | K2: 1 | L2: 1 | M2: 1 | N2: =SUM(C2:M2) -> 13
A3: 6002 | B3: Toluca de Lerdo | C3: 1 | D3: 1 | E3: 1 | F3: 1 | G3: 1 | H3: 1 | I3: 2 | J3: 1 | K3: 1 | L3: 1 | M3: 1 | N3: =SUM(C3:M3) -> 12
A4: 6003 | B4: Chimaihuacan | C4: 1 | D4: 1 | E4: 1 | F4: 1 | G4: 1 | H4: 1 | I4: 7 | J4: 1 | K4: 1 | L4: 1 | M4: 1 | N4: =SUM(C4:M4) -> 17
A5: 6004 | B5: Lerma de Villada | C5: 1 | D5: 1 | E5: 1 | F5: 1 | G5: 1 | H5: 1 | I5: 2 | J5: 1 | K5: 1 | L5: 1 | M5: 1 | N5: =SUM(C5:M5) -> 12
A6: 6005 | B6: Chimalhuacan | C6: 1 | D6: 1 | E6: 1 | F6: 1 | G6: 1 | H6: 1 | I6: 3 | J6: 1 | K6: 1 | L6: 1 | M6: 1 | N6: =SUM(C6:M6) -> 13
A7: 6006 | B7: Ecatepec de Morelos | C7: 1 | D7: 1 | E7: 1 | F7: 1 | G7: 1 | H7: 1 | I7: 3 | J7: 1 | K7: 1 | L7: 1 | M7: 1 | N7: =SUM(C7:M7) -> 13
A8: 6007 | B8: Tenancingo de Degollado | C8: 1 | D8: 1 | E8: 1 | F8: 1 | G8: 1 | H8: 1 | I8: 5 | J8: 1 | K8: 1 | L8: 1 | M8: 1 | N8: =SUM(C8:M8) -> 15
A9: 6008 | B9: Ecatepec de Morelos | C9: 1 | D9: 1 | E9: 1 | F9: 1 | G9: 1 | H9: 1 | I9: 6 | J9: 1 | K9: 1 | L9: 1 | M9: 1 | N9: =SUM(C9:M9) -> 16
A10: 6009 | B10: Tejupilco de Hidalgo | C10: 1 | D10: 1 | E10: 1 | F10: 1 | G10: 1 | H10: 1 | I10: 4 | J10: 1 | K10: 1 | L10: 1 | M10: 1 | N10: =SUM(C10:M10) -> 14
A11: 6010 | B11: Valle de Bravo | C11: 1 | D11: 1 | E11: 1 | F11: 1 | G11: 1 | H11: 1 | I11: 3 | J11: 1 | K11: 1 | L11: 1 | M11: 1 | N11: =SUM(C11:M11) -> 13
A12: 6011 | B12: Tultitlan de Mariano Escobedo | C12: 1 | D12: 1 | E12: 1 | F12: 1 | G12: 1 | H12: 1 | I12: 3 | J12: 1 | K12: 1 | L12: 1 | M12: 1 | N12: =SUM(C12:M12) -> 13
A13: 6012 | B13: Teoloyucan | C13: 1 | D13: 1 | E13: 1 | F13: 1 | G13: 1 | H13: 1 | I13: 3 | J13: 1 | K13: 1 | L13: 1 | M13: 1 | N13: =SUM(C13:M13) -> 13
... A46: 6045 | B46: Barrio la Cabecera 3a Seccion (Almoloya de Juarez) | C46: 1 | D46: 1 | E46: 1 | F46: 1 | G46: 1 | H46: 1 | I46: 3 | J46: 1 | K46: 1 | L46: 1 | M46: 1 | N46: =SUM(C46:M46) -> 13

Sheet BASE
A1: Clave | B1: Localidad
A2: 6001 | B2: Chalco de Diaz Covarrubias
A3: 6002 | B3: Toluca de Lerdo
A4: 6003 | B4: Chimaihuacan
A5: 6004 | B5: Lerma de Villada
A6: 6005 | B6: Chimalhuacan
A7: 6006 | B7: Ecatepec de Morelos
A8: 6007 | B8: Tenancingo de Degollado
A9: 6008 | B9: Ecatepec de Morelos
A10: 6009 | B10: Tejupilco de Hidalgo
A11: 6010 | B11: Valle de Bravo
A12: 6011 | B12: Tultitlan de Mariano Escobedo
A13: 6012 | B13: Teoloyucan
... A46: 6045 | B46: Barrio la Cabecera 3a Seccion (Almoloya de Juarez)

Sheet HORARIOS
A1: CONCAT | B1: Centro de Costo | C1: Distrito Electoral | D1: Hora de embarque | E1: Hora de llegada | F1: Volumen | G1: Unidades | H1: Día | I1: Ruta
A2: =B2&I2 -> 60281 | B2: 6028 | C2: Amecameca de Juárez | D2: 0.33333333 | E2: 13:00 hrs | F2: 70 | G2: 24 | H2: Día 1 | I2: 1
A3: =B3&I3 -> 60401 | B3: 6040 | C3: Ixtapaluca | D3: 0.375 | E3: 16:30 hrs | F3: 70 | H3: Día 1 | I3: 1
A4: =B4&I4 -> 60032 | B4: 6003 | C4: Chimalhuacán | D4: 0.4375 | E4: 14:00 hrs | F4: 50 | G4: 10 | H4: Día 1 | I4: 2
A5: =B5&I5 -> 60053 | B5: 6005 | C5: Chimalhuacán | D5: 0.47916667 | E5: 15:00 hrs | F5: 70 | G5: 24 | H5: Día 1 | I5: 3
A6: =B6&I6 -> 60314 | B6: 6031 | C6: Los Reyes Acaquilpan | D6: 0.47916667 | E6: 16:00 hrs | F6: 70 | G6: 24 | H6: Día 1 | I6: 4
A7: =B7&I7 -> 60414 | B7: 6041 | C7: Cd. Nezahualcóyotl | D7: 0.52083333 | E7: 18:00 hrs | F7: 70 | H7: Día 1 | I7: 4
A8: =B8&I8 -> 60325 | B8: 6032 | C8: Naucalpan de Juárez | D8: 0.5625 | E8: 17:00 hrs | F8: 50 | G8: 10 | H8: Día 1 | I8: 5
A9: =B9&I9 -> 60306 | B9: 6030 | C9: Naucalpan de Juárez | D9: 0.60416667 | E9: 18:0 hrs | F9: 50 | G9: 10 | H9: Día 1 | I9: 6
A10: =B10&I10 -> 60067 | B10: 6006 | C10: Ecatepec de Morelos | D10: 0.33333333 | E10: 12:00 hrs | F10: 70 | G10: 24 | H10: Día 2 | I10: 7
A11: =B11&I11 -> 60218 | B11: 6021 | C11: Ecatepec de Morelos | D11: 0.39583333 | E11: 13:30 hrs | F11: 70 | G11: 24 | H11: Día 2 | I11: 8
A12: =B12&I12 -> 60209 | B12: 6020 | C12: Zumpango de Ocampo | D12: 0.4375 | E12: 14:30 hrs | F12: 50 | G12: 10 | H12: Día 2 | I12: 9
A13: =B13&I13 -> 602610 | B13: 6026 | C13: Cuautitlán Izcalli | D13: 0.47916667 | E13: 15:00 hrs | F13: 70 | G13: 24 | H13: Día 2 | I13: 10
A14: =B14&I14 -> 601211 | B14: 6012 | C14: Teoloyucan | D14: 0.52083333 | E14: 17:00 hrs | F14: 70 | G14: 24 | H14: Día 2 | I14: 11
A15: =B15&I15 -> 604311 | B15: 6043 | C15: Cuautitlán Izcalli | D15: 0.5625 | E15: 19:00 hrs | F15: 70 | H15: Día 2 | I15: 11
A16: =B16&I16 -> 600212 | B16: 6002 | C16: Toluca de Lerdo | D16: 0.60416667 | E16: 16:30 hrs | F16: 70 | G16: 24 | H16: Día 2 | I16: 12
A17: =B17&I17 -> 603413 | B17: 6034 | C17: Toluca de Lerdo | D17: 0.64583333 | E17: 18:30 hrs | F17: 70 | G17: 24 | H17: Día 2 | I17: 13
A18: =B18&I18 -> 602214 | B18: 6022 | C18: Ojo de Agua (Tecámac) | D18: 0.33333333 | E18: 12:00 hrs | F18: 70 | G18: 24 | H18: Día 3 | I18: 14
A19: =B19&I19 -> 603315 | B19: 6033 | C19: Ojo de agua (Tecámac) | D19: 0.375 | E19: 13:00 hrs | F19: 70 | G19: 24 | H19: Día 3 | I19: 15
A20: =B20&I20 -> 604216 | B20: 6042 | C20: Ecatepec de Morelos | D20: 0.41666667 | E20: 13:30 hrs | F20: 50 | G20: 10 | H20: Día 3 | I20: 16
A21: =B21&I21 -> 600817 | B21: 6008 | C21: Ecatepec de Morelos | D21: 0.45833333 | E21: 15:00 hrs | F21: 50 | G21: 10 | H21: Día 3 | I21: 17
A22: =B22&I22 -> 601518 | B22: 6015 | C22: Ixtlahuaca de Rayón | D22: 0.5 | E22: 14:30 hrs | F22: 70 | G22: 24 | H22: Día 3 | I22: 18
A23: =B23&I23 -> 604518 | B23: 6045 | C23: Barrio la Cabecera 3a Sección (Almoloya de Juárez) | D23: 0.54166667 | E23: 16:00 hrs | F23: 70 | H23: Día 3 | I23: 18
A24: =B24&I24 -> 603619 | B24: 6036 | C24: San Miguel Zinacantepec | D24: 0.58333333 | E24: 17:30 hrs | F24: 70 | G24: 24 | H24: Día 3 | I24: 19
A25: =B25&I25 -> 603519 | B25: 6035 | C25: Metepec | D25: 0.625 | E25: 19:00 hrs | F25: 70 | H25: Día 3 | I25: 19
A26: =B26&I26 -> 602322 | B26: 6023 | C26: Texcoco de Mora | D26: 0.33333333 | E26: 12:30 hrs | F26: 70 | G26: 24 | H26: Día 4 | I26: 22
A27: =B27&I27 -> 603922 | B27: 6039 | C27: Tepexpan (Acolman) | D27: 0.375 | E27: 13:00 hrs | F27: 70 | H27: Día 4 | I27: 22
A28: =B28&I28 -> 603720 | B28: 6037 | C28: Tlalnepantla de Baz | D28: 0.41666667 | E28: 13:30 hrs | F28: 70 | G28: 24 | H28: Día 4 | I28: 20
A29: =B29&I29 -> 601821 | B29: 6018 | C29: Tlalnepantla de Baz | D29: 0.45833333 | E29: 14:30 hrs | F29: 70 | G29: 24 | H29: Día 4 | I29: 21
A30: =B30&I30 -> 601423 | B30: 6014 | C30: Jilotepec de Andrés Molina Enríquez | D30: 0.5 | E30: 16:00 hrs | F30: 70 | G30: 24 | H30: Día 4 | I30: 23
A31: =B31&I31 -> 601323 | B31: 6013 | C31: Atlacomulco de Fabela | D31: 0.54166667 | E31: 18:30 hrs | F31: 70 | H31: Día 4 | I31: 23
A32: =B32&I32 -> 600424 | B32: 6004 | C32: Lerma de Villada | D32: 0.58333333 | E32: 17:00 hrs | F32: 70 | G32: 24 | H32: Día 4 | I32: 24
A33: =B33&I33 -> 601724 | B33: 6017 | C33: Huixquilucan de Degollado | D33: 0.625 | E33: 19:30 hrs | F33: 70 | H33: Día 4 | I33: 24
A34: =B34&I34 -> 600125 | B34: 6001 | C34: Chalco de Díaz Covarrubias | D34: 0.33333333 | E34: 12:00 hrs | F34: 70 | G34: 24 | H34: Dia 5 | I34: 25
A35: =B35&I35 -> 602726 | B35: 6027 | C35: Valle de Chalco Solidaridad | D35: 0.375 | E35: 13:00 hrs | F35: 50 | G35: 10 | H35: Dia 5 | I35: 26
A36: =B36&I36 -> 604427 | B36: 6044 | C36: Nicolás Romero | D36: 0.41666667 | E36: 13:30 hrs | F36: 50 | G36: 10 | H36: Dia 5 | I36: 27
A37: =B37&I37 -> 601628 | B37: 6016 | C37: Ciudad Adolfo López Mateos | D37: 0.45833333 | E37: 15:30 hrs | F37: 70 | G37: 24 | H37: Dia 5 | I37: 28
A38: =B38&I38 -> 601928 | B38: 6019 | C38: Santa María Tultepec | D38: 0.5 | E38: 17:00 hrs | F38: 70 | H38: Dia 5 | I38: 28
A39: =B39&I39 -> 601029 | B39: 6010 | C39: Valle de Bravo | D39: 0.54166667 | E39: 16:30 hrs | F39: 50 | G39: 10 | H39: Dia 5 | I39: 29
A40: =B40&I40 -> 600930 | B40: 6009 | C40: Tejupilco de Hidalgo | D40: 0.58333333 | E40: 17:00 hrs | F40: 50 | G40: 10 | H40: Dia 5 | I40: 30
...
